<?xml version="1.0" ?>
<!-- =================================================================================== -->
<!-- |    This document was autogenerated by xacro from jaco_standalone.urdf.xacro     | -->
<!-- |    EDITING THIS FILE BY HAND IS NOT RECOMMENDED                                 | -->
<!-- =================================================================================== -->
<robot name="jaco" xmlns:controller="http://playerstage.sourceforge.net/gazebo/xmlschema/#controller" xmlns:interface="http://playerstage.sourceforge.net/gazebo/xmlschema/#interface" xmlns:sensor="http://playerstage.sourceforge.net/gazebo/xmlschema/#sensor" xmlns:xacro="http://ros.org/wiki/xacro">
  <link name="base_link1"/>
  <joint name="base_joint" type="fixed">
    <parent link="base_link1"/>
    <child link="jaco_base_link"/>
    <origin xyz="0 0 0"/>
  </joint>
  <gazebo>
    <plugin filename="libgazebo_ros_controller_manager.so" name="gazebo_ros_controller_manager">
      <alwaysOn>true</alwaysOn>
      <updateRate>1000.0</updateRate>
      <robotParam>robot_description</robotParam>
    </plugin>
  </gazebo>
  <transmission name="jaco_1_trans" type="pr2_mechanism_model/SimpleTransmission">
    <actuator name="jaco_1_motor"/>
    <joint name="jaco_joint_1"/>
    <mechanicalReduction>1</mechanicalReduction>
    <motorTorqueConstant>1</motorTorqueConstant>
  </transmission>
  <transmission name="jaco_2_trans" type="pr2_mechanism_model/SimpleTransmission">
    <actuator name="jaco_2_motor"/>
    <joint name="jaco_joint_2"/>
    <mechanicalReduction>1</mechanicalReduction>
    <motorTorqueConstant>1</motorTorqueConstant>
  </transmission>
  <transmission name="jaco_3_trans" type="pr2_mechanism_model/SimpleTransmission">
    <actuator name="jaco_3_motor"/>
    <joint name="jaco_joint_3"/>
    <mechanicalReduction>1</mechanicalReduction>
    <motorTorqueConstant>1</motorTorqueConstant>
  </transmission>
  <transmission name="jaco_4_trans" type="pr2_mechanism_model/SimpleTransmission">
    <actuator name="jaco_4_motor"/>
    <joint name="jaco_joint_4"/>
    <mechanicalReduction>1</mechanicalReduction>
    <motorTorqueConstant>1</motorTorqueConstant>
  </transmission>
  <transmission name="jaco_5_trans" type="pr2_mechanism_model/SimpleTransmission">
    <actuator name="jaco_5_motor"/>
    <joint name="jaco_joint_5"/>
    <mechanicalReduction>1</mechanicalReduction>
    <motorTorqueConstant>1</motorTorqueConstant>
  </transmission>
  <transmission name="jaco_6_trans" type="pr2_mechanism_model/SimpleTransmission">
    <actuator name="jaco_6_motor"/>
    <joint name="jaco_joint_6"/>
    <mechanicalReduction>1</mechanicalReduction>
    <motorTorqueConstant>1</motorTorqueConstant>
  </transmission>
  <transmission name="jaco_finger_1_trans" type="pr2_mechanism_model/SimpleTransmission">
    <actuator name="jaco_finger_1_motor"/>
    <joint name="jaco_finger_joint_1"/>
    <mechanicalReduction>1</mechanicalReduction>
    <motorTorqueConstant>1</motorTorqueConstant>
  </transmission>
  <transmission name="jaco_finger_2_trans" type="pr2_mechanism_model/SimpleTransmission">
    <actuator name="jaco_finger_2_motor"/>
    <joint name="jaco_finger_joint_2"/>
    <mechanicalReduction>1</mechanicalReduction>
    <motorTorqueConstant>1</motorTorqueConstant>
  </transmission>
  <transmission name="jaco_finger_3_trans" type="pr2_mechanism_model/SimpleTransmission">
    <actuator name="jaco_finger_3_motor"/>
    <joint name="jaco_finger_joint_3"/>
    <mechanicalReduction>1</mechanicalReduction>
    <motorTorqueConstant>1</motorTorqueConstant>
  </transmission>
  <material name="JacoGrey">
    <color rgba="0.2 0.2 0.9 1.0"/>
  </material>
  <link name="jaco_base_link">
    <inertial>
      <mass value="1"/>
      <!--origin xyz="0 0 -0.0525" rpy="0 0 0"/-->
      <origin rpy="0 0 0" xyz="0 0 0.0"/>
      <inertia ixx="1" ixy="0" ixz="0" iyy="1" iyz="0" izz="1"/>
    </inertial>
    <visual>
      <material name="JacoGrey"/>
      <!--origin xyz="0 0 -0.0525" rpy="0 0 0"/-->
      <geometry>
        <mesh filename="package://jaco_description/meshes/joint_1.stl" scale="0.001 0.001 0.001"/>
      </geometry>
    </visual>
    <collision>
      <!--origin xyz="0 0 -0.0525" rpy="0 0 0"/-->
      <geometry>
        <mesh filename="package://jaco_description/meshes/joint_1.stl" scale="0.001 0.001 0.001"/>
      </geometry>
    </collision>
  </link>
  <gazebo reference="jaco_base_link">
    <material>Gazebo/Yellow</material>
    <turnGravityOff>true</turnGravityOff>
  </gazebo>
  <joint name="jaco_joint_1" type="revolute">
    <!--origin xyz="0 0 0.2102" rpy="0 0 0"/-->
    <origin rpy="0 0 0" xyz="0 0 0.2725"/>
    <axis rpy="0 0 0" xyz="0 0 -1"/>
    <parent link="jaco_base_link"/>
    <child link="jaco_link_1"/>
    <limit effort="10" lower="-0.2" upper="0.2" velocity="1"/>
  </joint>
  <link name="jaco_link_1">
    <inertial>
      <mass value="1"/>
      <inertia ixx="1" ixy="0" ixz="0" iyy="1" iyz="0" izz="1"/>
      <origin/>
    </inertial>
    <visual>
      <material name="JacoGrey"/>
      <origin rpy="0 0 -1.570796327" xyz="0 0 -0.12"/>
      <geometry>
        <mesh filename="package://jaco_description/meshes/joint_2.stl" scale="0.001 0.001 0.001"/>
      </geometry>
    </visual>
    <collision>
      <origin rpy="0 0 -1.570796327" xyz="0 0 -0.12"/>
      <geometry>
        <mesh filename="package://jaco_description/meshes/joint_2.stl" scale="0.001 0.001 0.001"/>
      </geometry>
    </collision>
  </link>
  <gazebo reference="jaco_link_1">
    <material>Gazebo/Yellow</material>
    <turnGravityOff>true</turnGravityOff>
  </gazebo>
  <joint name="jaco_joint_2" type="revolute">
    <origin rpy="-1.570796327 0 0" xyz="0 0 0"/>
    <axis xyz="0 0 1"/>
    <parent link="jaco_link_1"/>
    <child link="jaco_link_2"/>
    <limit effort="10" lower="-0.6" upper="0.65" velocity="1"/>
  </joint>
  <link name="jaco_link_2">
    <inertial>
      <mass value="1"/>
      <inertia ixx="1" ixy="0" ixz="0" iyy="1" iyz="0" izz="1"/>
      <origin/>
    </inertial>
    <visual>
      <material name="JacoGrey"/>
      <origin rpy="0 1.570796327 0" xyz="0 0 0.015"/>
      <geometry>
        <mesh filename="package://jaco_description/meshes/joint_3.stl" scale="0.001 0.001 0.001"/>
      </geometry>
    </visual>
    <collision>
      <origin rpy="0 1.570796327 0" xyz="0 0 0.015"/>
      <geometry>
        <mesh filename="package://jaco_description/meshes/joint_3.stl" scale="0.001 0.001 0.001"/>
      </geometry>
    </collision>
  </link>
  <gazebo reference="jaco_link_2">
    <material>Gazebo/Yellow</material>
    <turnGravityOff>true</turnGravityOff>
  </gazebo>
  <joint name="jaco_joint_3" type="revolute">
    <origin rpy="0 0 0" xyz="0.4100 0 0.012"/>
    <axis xyz="0 0 -1"/>
    <parent link="jaco_link_2"/>
    <child link="jaco_link_3"/>
    <limit effort="10" lower="-0.1" upper="0.1" velocity="1"/>
  </joint>
  <link name="jaco_link_3">
    <inertial>
      <mass value="1"/>
      <inertia ixx="1" ixy="0" ixz="0" iyy="1" iyz="0" izz="1"/>
      <origin/>
    </inertial>
    <visual>
      <material name="JacoGrey"/>
      <origin rpy="0 1.570796327 1.570796327" xyz="0 0 -0.012"/>
      <geometry>
        <mesh filename="package://jaco_description/meshes/joint_4.stl" scale="1.000 1.000 1.000"/>
      </geometry>
    </visual>
    <collision>
      <origin rpy="0 1.570796327 1.570796327" xyz="0 0 -0.012"/>
      <geometry>
        <mesh filename="package://jaco_description/meshes/joint_4.stl" scale="1.000 1.000 1.000"/>
      </geometry>
    </collision>
  </link>
  <gazebo reference="jaco_link_3">
    <material>Gazebo/Yellow</material>
    <turnGravityOff>true</turnGravityOff>
  </gazebo>
  <joint name="jaco_joint_4" type="revolute">
    <origin rpy="-1.570796327 0 0" xyz="0 0.24927682300748782 0 "/>
    <axis xyz="0 0 -1"/>
    <parent link="jaco_link_3"/>
    <child link="jaco_link_4"/>
    <limit effort="10" lower="2.44" upper="2.46" velocity="1"/>
  </joint>
  <link name="jaco_link_4">
    <inertial>
      <mass value="1"/>
      <inertia ixx="1" ixy="0" ixz="0" iyy="1" iyz="0" izz="1"/>
      <origin/>
    </inertial>
    <visual>
      <material name="JacoGrey"/>
      <origin rpy="0 0 -1.570796327" xyz="0 0 -0.042276823"/>
      <geometry>
        <mesh filename="package://jaco_description/meshes/joint_5.stl" scale="0.001 0.001 0.001"/>
      </geometry>
    </visual>
    <collision>
      <origin rpy="0 0 -1.570796327" xyz="0 0 -0.042276823"/>
      <geometry>
        <mesh filename="package://jaco_description/meshes/joint_5.stl" scale="0.001 0.001 0.001"/>
      </geometry>
    </collision>
  </link>
  <gazebo reference="jaco_link_4">
    <material>Gazebo/Yellow</material>
    <turnGravityOff>true</turnGravityOff>
  </gazebo>
  <joint name="jaco_joint_5" type="revolute">
    <origin rpy="0.959931089 0 0" xyz="0 -0.069262292 0.048497979"/>
    <axis xyz="0 0 -1"/>
    <parent link="jaco_link_4"/>
    <child link="jaco_link_5"/>
    <limit effort="10" lower="2.48" upper="2.5" velocity="1"/>
  </joint>
  <link name="jaco_link_5">
    <inertial>
      <mass value="1.0"/>
      <inertia ixx="1" ixy="0" ixz="0" iyy="1" iyz="0" izz="1"/>
      <origin/>
    </inertial>
    <visual>
      <material name="JacoGrey"/>
      <origin rpy="0 -0.959931089 1.570796327" xyz="0 0 -0.042276823"/>
      <geometry>
        <mesh filename="package://jaco_description/meshes/joint_6.stl" scale="0.001 0.001 0.001"/>
      </geometry>
    </visual>
    <collision>
      <origin rpy="0 -0.959931089 1.570796327" xyz="0 0 -0.042276823"/>
      <geometry>
        <mesh filename="package://jaco_description/meshes/joint_6.stl" scale="0.001 0.001 0.001"/>
      </geometry>
    </collision>
  </link>
  <gazebo reference="jaco_link_5">
    <material>Gazebo/Yellow</material>
    <turnGravityOff>true</turnGravityOff>
  </gazebo>
  <joint name="jaco_joint_6" type="revolute">
    <!--origin xyz="0 -0.186174274 0.13036063" rpy="0.959931089 0 0"/-->
    <origin rpy="-0.959931089 0 3.1415926535897931" xyz="0 -0.186174274 0.13036063"/>
    <!--<origin xyz="0 0 0" rpy="0 0 -3.14"/>-->
    <axis xyz="0 0 -1"/>
    <parent link="jaco_link_5"/>
    <child link="jaco_link_6"/>
    <limit effort="10" lower="1.86" upper="1.88" velocity="1"/>
  </joint>
  <link name="jaco_link_6">
    <inertial>
      <mass value="0.3"/>
      <inertia ixx="1" ixy="0" ixz="0" iyy="1" iyz="0" izz="1"/>
      <origin/>
    </inertial>
    <visual>
      <material name="JacoGrey"/>
      <origin rpy="0 0 -3.1415926535897931" xyz="0 0 -0.1850"/>
      <!--<origin xyz="0 0 -0.1850" rpy="0 0 0"/>      -->
      <geometry>
        <mesh filename="package://jaco_description/meshes/hand_with_noFinger.stl" scale="0.001 0.001 0.001"/>
      </geometry>
    </visual>
    <collision>
      <origin rpy="0 0 -3.1415926535897931" xyz="0 0 -0.1850"/>
      <!--<origin xyz="0 0 -0.1850" rpy="0 0 0"/>-->
      <geometry>
        <mesh filename="package://jaco_description/meshes/hand_with_noFinger.stl" scale="0.001 0.001 0.001"/>
      </geometry>
    </collision>
  </link>
  <gazebo reference="jaco_link_6">
    <material>Gazebo/Yellow</material>
    <turnGravityOff>true</turnGravityOff>
  </gazebo>
  <joint name="jaco_gripper_tool_frame_joint" type="fixed">
    <parent link="jaco_link_6"/>
    <child link="jaco_gripper_tool_frame"/>
    <origin rpy="0.23 -1.570796327 1.570796327" xyz="0 0 -0.08"/>
  </joint>
  <link name="jaco_gripper_tool_frame">
    <!-- This is the coordinate system of the tool (this is the position
         used in IK etc., relative to the base frame); there is no actual
         arm part attached to this link -->
  </link>
  <joint name="jaco_finger_joint_1" type="revolute">
    <!--origin xyz="-0.036 -0.021 -0.07" rpy="0 0 0"/-->
    <!-- changed becuase it look funny in simulation-->
    <origin rpy="0 0 3.14159265359" xyz="0.036 -0.021 -0.09"/>
    <axis xyz="0 1 0"/>
    <parent link="jaco_link_6"/>
    <child link="jaco_finger_link_1"/>
    <limit effort="10" lower="0.001" upper="0.5" velocity="1"/>
  </joint>
  <link name="jaco_finger_link_1">
    <inertial>
      <mass value="0.05"/>
      <inertia ixx="1" ixy="0" ixz="0" iyy="1" iyz="0" izz="1"/>
      <origin/>
    </inertial>
    <visual>
      <origin rpy="0 0 0" xyz="0 0 0"/>
      <geometry>
        <mesh filename="package://jaco_description/meshes/finger.stl" scale="1 1 1"/>
      </geometry>
    </visual>
    <collision>
      <origin rpy="0 0 0" xyz="0 0 0"/>
      <geometry>
        <mesh filename="package://jaco_description/meshes/finger.stl" scale="1 1 1"/>
      </geometry>
    </collision>
  </link>
  <gazebo reference="jaco_finger_link_1">
    <material>Gazebo/Yellow</material>
    <turnGravityOff>true</turnGravityOff>
  </gazebo>
  <joint name="jaco_finger_joint_2" type="revolute">
    <!--origin xyz="-0.036 0.021 -0.07" rpy="0 0 0"/-->
    <origin rpy="0 0 3.37159265359" xyz="0.036 0.021 -0.09"/>
    <axis xyz="0 1 0"/>
    <parent link="jaco_link_6"/>
    <child link="jaco_finger_link_2"/>
    <limit effort="10" lower="0.004" upper="0.5" velocity="1"/>
  </joint>
  <link name="jaco_finger_link_2">
    <inertial>
      <mass value="0.05"/>
      <inertia ixx="1" ixy="0" ixz="0" iyy="1" iyz="0" izz="1"/>
      <origin/>
    </inertial>
    <visual>
      <origin rpy="0 0 0" xyz="0 0 0"/>
      <geometry>
        <mesh filename="package://jaco_description/meshes/finger.stl" scale="1 1 1"/>
      </geometry>
    </visual>
    <collision>
      <origin rpy="0 0 0" xyz="0 0 0"/>
      <geometry>
        <mesh filename="package://jaco_description/meshes/finger.stl" scale="1 1 1"/>
      </geometry>
    </collision>
  </link>
  <gazebo reference="jaco_finger_link_2">
    <material>Gazebo/Yellow</material>
    <turnGravityOff>true</turnGravityOff>
  </gazebo>
  <joint name="jaco_finger_joint_3" type="revolute">
    <!--origin xyz="0.036 -0 -0.07" rpy="0 0 3.14"/-->
    <origin rpy="0 0 0.23" xyz="-0.036 -0 -0.09"/>
    <axis xyz="0 1 0"/>
    <parent link="jaco_link_6"/>
    <child link="jaco_finger_link_3"/>
    <limit effort="10" lower="0.004" upper="0.5" velocity="1"/>
  </joint>
  <link name="jaco_finger_link_3">
    <inertial>
      <mass value="0.05"/>
      <inertia ixx="1" ixy="0" ixz="0" iyy="1" iyz="0" izz="1"/>
      <origin/>
    </inertial>
    <visual>
      <origin rpy="0 0 0" xyz="0 0 0"/>
      <geometry>
        <mesh filename="package://jaco_description/meshes/finger.stl" scale="1 1 1"/>
      </geometry>
    </visual>
    <collision>
      <origin rpy="0 0 0" xyz="0 0 0"/>
      <geometry>
        <mesh filename="package://jaco_description/meshes/finger.stl" scale="1 1 1"/>
      </geometry>
    </collision>
  </link>
  <gazebo reference="jaco_finger_link_3">
    <material>Gazebo/Yellow</material>
    <turnGravityOff>true</turnGravityOff>
  </gazebo>
</robot>

