<?xml version="1.0" ?>
<!-- =================================================================================== -->
<!-- |    This document was autogenerated by xacro from msi.xacro                      | -->
<!-- |    EDITING THIS FILE BY HAND IS NOT RECOMMENDED                                 | -->
<!-- =================================================================================== -->
<robot name="mars_rover_iitb" xmlns:xacro="http://ros.org/wiki/xacro">
  <gazebo>
    <plugin filename="librover_gazebo.so" name="drive_controller">
    <topicName value="cmd_vel"/>
    </plugin>
  </gazebo>
  <!-- Included URDF/XACRO Files -->
  <!-- <xacro:include filename="$(find husky_description)/urdf/decorations.urdf.xacro" /> -->
  <!-- <xacro:include filename="$(find msi_2k16_17_urdf)/urdf/hokuyo.urdf.xacro" /> -->
  <!--<xacro:include filename="$(find msi_2k16_17_urdf)/urdf/arm.urdf" />-->
  <material name="chassis">
    <color rgba="0.67 0.78 0.85 1"/>
  </material>
  <!-- Base Size -->
  <!-- Wheel Properties -->
  <!-- Wheel Mounting Positions -->
  <!-- Base link is the center of the robot's bottom plate -->
  <link name="base_link">
    <visual>
      <geometry>
        <mesh filename="package://msi_2k16_17_urdf/meshes/chassis.stl" scale="0.01 0.01 0.01"/>
      </geometry>
      <origin rpy="0 0 -1.570795" xyz="0 0 0"/>
      <material name="chassis"/>
    </visual>
  </link>
  <gazebo reference="base_link">
    <material> Gazebo/Grey</material>
  </gazebo>
  <link name="rocker_R">
    <visual>
      <geometry>
        <mesh filename="package://msi_2k16_17_urdf/meshes/rocker_MIR.stl" scale="0.01 0.01 0.01"/>
      </geometry>
      <origin rpy="0 0 0" xyz="0 0 0"/>
      <material name="chassis"/>
    </visual>
    <inertial>
      <origin rpy="0 0 0" xyz="0 0 1"/>
      <mass value="1"/>
      <inertia ixx="1.0" ixy="0.0" ixz="0.0" iyy="1.0" iyz="0.0" izz="1.0"/>
    </inertial>
  </link>
  <joint name="rocker_R_to_chassis" type="revolute">
    <origin rpy="0 0 0" xyz=" 0 0.335 0"/>
    <parent link="base_link"/>
    <child link="rocker_R"/>
    <limit effort="20" lower="-0.17" upper="0.17" velocity="1"/>
    <axis rpy="0 0 0" xyz="0 1 0"/>
  </joint>
  <link name="rocker_L">
    <visual>
      <geometry>
        <mesh filename="package://msi_2k16_17_urdf/meshes/rocker.stl" scale="0.01 0.01 0.01"/>
      </geometry>
      <origin rpy="0 0 0" xyz="0 0 0"/>
      <material name="chassis"/>
    </visual>
    <inertial>
      <origin rpy="0 0 0" xyz="0 0 1"/>
      <mass value="1"/>
      <inertia ixx="1.0" ixy="0.0" ixz="0.0" iyy="1.0" iyz="0.0" izz="1.0"/>
    </inertial>
  </link>
  <joint name="rocker_L_to_chassis" type="revolute">
    <origin rpy="0 0 0" xyz=" 0 -0.315 0"/>
    <parent link="base_link"/>
    <child link="rocker_L"/>
    <limit effort="20" lower="-0.17" upper="0.17" velocity="1"/>
    <axis rpy="0 0 0" xyz="0 1 0"/>
  </joint>
  <link name="bogie_R">
    <visual>
      <geometry>
        <mesh filename="package://msi_2k16_17_urdf/meshes/bogie.stl" scale="0.01 0.01 0.01"/>
      </geometry>
      <origin rpy="0 0 0" xyz="0 0 0"/>
      <material name="chassis"/>
    </visual>
    <inertial>
      <origin rpy="0 0 0" xyz="0 0 1"/>
      <mass value="1"/>
      <inertia ixx="1.0" ixy="0.0" ixz="0.0" iyy="1.0" iyz="0.0" izz="1.0"/>
    </inertial>
  </link>
  <joint name="bogie_R_to_rocker" type="revolute">
    <origin rpy="0 0 0" xyz="-0.202 0.0200 -0.1434"/>
    <parent link="rocker_R"/>
    <child link="bogie_R"/>
    <limit effort="20" lower="-0.17" upper="0.17" velocity="1"/>
    <axis rpy="0 0 0" xyz="0 1 0"/>
  </joint>
  <link name="bogie_L">
    <visual>
      <geometry>
        <mesh filename="package://msi_2k16_17_urdf/meshes/bogie.stl" scale="0.01 0.01 0.01"/>
      </geometry>
      <origin rpy="0 0 0" xyz="0 0 0"/>
      <material name="chassis"/>
    </visual>
    <inertial>
      <origin rpy="0 0 0" xyz="0 0 1"/>
      <mass value="1"/>
      <inertia ixx="1.0" ixy="0.0" ixz="0.0" iyy="1.0" iyz="0.0" izz="1.0"/>
    </inertial>
  </link>
  <joint name="bogie_L_to_rocker" type="revolute">
    <origin rpy="0 0 0" xyz="-0.202 -0.044 -0.1434 "/>
    <parent link="rocker_L"/>
    <child link="bogie_L"/>
    <limit effort="20" lower="-0.17" upper="0.17" velocity="1"/>
    <axis rpy="0 0 0" xyz="0 1 0"/>
  </joint>
  <!-- Base footprint is on the ground under the robot -->
  <link name="base_footprint"/>
  <joint name="base_footprint_joint" type="fixed">
    <origin rpy="0 0 0" xyz="0 0 -0.345"/>
    <parent link="base_link"/>
    <child link="base_footprint"/>
  </joint>
  <!-- Interial link stores the robot's inertial information -->
  <link name="inertial_link">
    <inertial>
      <mass value="33.455"/>
      <origin xyz="-0.08748 -0.00085 0.09947"/>
      <inertia ixx="0.6022" ixy="-0.02364" ixz="-0.1197" iyy="1.7386" iyz="-0.001544" izz="2.0296"/>
    </inertial>
  </link>
  <joint name="inertial_joint" type="fixed">
    <origin rpy="0 0 0" xyz="0 0 0"/>
    <parent link="base_link"/>
    <child link="inertial_link"/>
  </joint>
  <!-- IMU Link is the standard mounting position for the UM6 IMU.-->
  <!-- Can be modified with environment variables in /etc/ros/setup.bash -->
  <link name="imu_link"/>
  <joint name="imu_joint" type="fixed">
    <origin rpy="0 -1.5708 3.1416" xyz="0.19 0 0.149"/>
    <parent link="base_link"/>
    <child link="imu_link"/>
  </joint>
  <gazebo reference="imu_link">
    </gazebo>
  <!-- wheel macros -->
  <link name="front_L_wheel_link">
    <inertial>
      <mass value="5"/>
      <origin xyz="0 0 0"/>
      <inertia ixx="0.02467" ixy="0" ixz="0" iyy="0.02467" iyz="0" izz="0.04411"/>
    </inertial>
    <visual>
      <origin rpy="0 0 1.570795" xyz="0 -0.09 0"/>
      <geometry>
        <mesh filename="package://msi_2k16_17_urdf/meshes/tyre.stl" scale="0.01 0.01 0.01"/>
      </geometry>
    </visual>
    <collision>
      <origin rpy="1.570795 0 0" xyz="0 0 0"/>
      <geometry>
        <cylinder length="0.18" radius="0.17"/>
      </geometry>
    </collision>
  </link>
  <gazebo reference="front_L_wheel_link">
    <mu1 value="1.0"/>
    <mu2 value="1.0"/>
    <kp value="10000000.0"/>
    <kd value="1.0"/>
    <fdir1 value="1 0 0"/>
    <material> Gazebo/FlatBlack</material>
  </gazebo>
  <joint name="front_L_wheel" type="continuous">
    <parent link="bogie_L"/>
    <child link="front_L_wheel_link"/>
    <origin rpy="0 0 0" xyz="-0.2348 -0.1146 -0.1932"/>
    <axis rpy="0 0 0" xyz="0 1 0"/>
  </joint>
  <transmission name="front_L_wheel_trans" type="SimpleTransmission">
    <type>transmission_interface/SimpleTransmission</type>
    <actuator name="front_L_wheel_motor">
      <mechanicalReduction>1</mechanicalReduction>
    </actuator>
    <joint name="front_L_wheel">
      <hardwareInterface>VelocityJointInterface</hardwareInterface>
    </joint>
  </transmission>
  <link name="front_R_wheel_link">
    <inertial>
      <mass value="5"/>
      <origin xyz="0 0 0"/>
      <inertia ixx="0.02467" ixy="0" ixz="0" iyy="0.02467" iyz="0" izz="0.04411"/>
    </inertial>
    <visual>
      <origin rpy="0 0 1.570795" xyz="0 -0.09 0"/>
      <geometry>
        <mesh filename="package://msi_2k16_17_urdf/meshes/tyre.stl" scale="0.01 0.01 0.01"/>
      </geometry>
    </visual>
    <collision>
      <origin rpy="1.570795 0 0" xyz="0 0 0"/>
      <geometry>
        <cylinder length="0.18" radius="0.17"/>
      </geometry>
    </collision>
  </link>
  <gazebo reference="front_R_wheel_link">
    <mu1 value="1.0"/>
    <mu2 value="1.0"/>
    <kp value="10000000.0"/>
    <kd value="1.0"/>
    <fdir1 value="1 0 0"/>
    <material> Gazebo/FlatBlack</material>
  </gazebo>
  <joint name="front_R_wheel" type="continuous">
    <parent link="bogie_R"/>
    <child link="front_R_wheel_link"/>
    <origin rpy="0 0 0" xyz="-0.2348 0.1146 -0.1932"/>
    <axis rpy="0 0 0" xyz="0 1 0"/>
  </joint>
  <transmission name="front_R_wheel_trans" type="SimpleTransmission">
    <type>transmission_interface/SimpleTransmission</type>
    <actuator name="front_R_wheel_motor">
      <mechanicalReduction>1</mechanicalReduction>
    </actuator>
    <joint name="front_R_wheel">
      <hardwareInterface>VelocityJointInterface</hardwareInterface>
    </joint>
  </transmission>
  <link name="rear_L_wheel_link">
    <inertial>
      <mass value="5"/>
      <origin xyz="0 0 0"/>
      <inertia ixx="0.02467" ixy="0" ixz="0" iyy="0.02467" iyz="0" izz="0.04411"/>
    </inertial>
    <visual>
      <origin rpy="0 0 1.570795" xyz="0 -0.09 0"/>
      <geometry>
        <mesh filename="package://msi_2k16_17_urdf/meshes/tyre.stl" scale="0.01 0.01 0.01"/>
      </geometry>
    </visual>
    <collision>
      <origin rpy="1.570795 0 0" xyz="0 0 0"/>
      <geometry>
        <cylinder length="0.18" radius="0.17"/>
      </geometry>
    </collision>
  </link>
  <gazebo reference="rear_L_wheel_link">
    <mu1 value="1.0"/>
    <mu2 value="1.0"/>
    <kp value="10000000.0"/>
    <kd value="1.0"/>
    <fdir1 value="1 0 0"/>
    <material> Gazebo/FlatBlack</material>
  </gazebo>
  <joint name="rear_L_wheel" type="continuous">
    <parent link="rocker_L"/>
    <child link="rear_L_wheel_link"/>
    <origin rpy="0 0 0" xyz="0.4947 -0.1083 -0.2738"/>
    <axis rpy="0 0 0" xyz="0 1 0"/>
  </joint>
  <transmission name="rear_L_wheel_trans" type="SimpleTransmission">
    <type>transmission_interface/SimpleTransmission</type>
    <actuator name="rear_L_wheel_motor">
      <mechanicalReduction>1</mechanicalReduction>
    </actuator>
    <joint name="rear_L_wheel">
      <hardwareInterface>VelocityJointInterface</hardwareInterface>
    </joint>
  </transmission>
  <link name="rear_R_wheel_link">
    <inertial>
      <mass value="5"/>
      <origin xyz="0 0 0"/>
      <inertia ixx="0.02467" ixy="0" ixz="0" iyy="0.02467" iyz="0" izz="0.04411"/>
    </inertial>
    <visual>
      <origin rpy="0 0 1.570795" xyz="0 -0.09 0"/>
      <geometry>
        <mesh filename="package://msi_2k16_17_urdf/meshes/tyre.stl" scale="0.01 0.01 0.01"/>
      </geometry>
    </visual>
    <collision>
      <origin rpy="1.570795 0 0" xyz="0 0 0"/>
      <geometry>
        <cylinder length="0.18" radius="0.17"/>
      </geometry>
    </collision>
  </link>
  <gazebo reference="rear_R_wheel_link">
    <mu1 value="1.0"/>
    <mu2 value="1.0"/>
    <kp value="10000000.0"/>
    <kd value="1.0"/>
    <fdir1 value="1 0 0"/>
    <material> Gazebo/FlatBlack</material>
  </gazebo>
  <joint name="rear_R_wheel" type="continuous">
    <parent link="rocker_R"/>
    <child link="rear_R_wheel_link"/>
    <origin rpy="0 0 0" xyz="0.4947 0.1083 -0.2738"/>
    <axis rpy="0 0 0" xyz="0 1 0"/>
  </joint>
  <transmission name="rear_R_wheel_trans" type="SimpleTransmission">
    <type>transmission_interface/SimpleTransmission</type>
    <actuator name="rear_R_wheel_motor">
      <mechanicalReduction>1</mechanicalReduction>
    </actuator>
    <joint name="rear_R_wheel">
      <hardwareInterface>VelocityJointInterface</hardwareInterface>
    </joint>
  </transmission>
  <link name="center_L_wheel_link">
    <inertial>
      <mass value="5"/>
      <origin xyz="0 0 0"/>
      <inertia ixx="0.02467" ixy="0" ixz="0" iyy="0.02467" iyz="0" izz="0.04411"/>
    </inertial>
    <visual>
      <origin rpy="0 0 1.570795" xyz="0 -0.09 0"/>
      <geometry>
        <mesh filename="package://msi_2k16_17_urdf/meshes/tyre.stl" scale="0.01 0.01 0.01"/>
      </geometry>
    </visual>
    <collision>
      <origin rpy="1.570795 0 0" xyz="0 0 0"/>
      <geometry>
        <cylinder length="0.18" radius="0.17"/>
      </geometry>
    </collision>
  </link>
  <gazebo reference="center_L_wheel_link">
    <mu1 value="1.0"/>
    <mu2 value="1.0"/>
    <kp value="10000000.0"/>
    <kd value="1.0"/>
    <fdir1 value="1 0 0"/>
    <material> Gazebo/FlatBlack</material>
  </gazebo>
  <joint name="center_L_wheel" type="continuous">
    <parent link="bogie_L"/>
    <child link="center_L_wheel_link"/>
    <origin rpy="0 0 0" xyz="0.2348 -0.1146 -0.1932"/>
    <axis rpy="0 0 0" xyz="0 1 0"/>
  </joint>
  <transmission name="center_L_wheel_trans" type="SimpleTransmission">
    <type>transmission_interface/SimpleTransmission</type>
    <actuator name="center_L_wheel_motor">
      <mechanicalReduction>1</mechanicalReduction>
    </actuator>
    <joint name="center_L_wheel">
      <hardwareInterface>VelocityJointInterface</hardwareInterface>
    </joint>
  </transmission>
  <link name="center_R_wheel_link">
    <inertial>
      <mass value="5"/>
      <origin xyz="0 0 0"/>
      <inertia ixx="0.02467" ixy="0" ixz="0" iyy="0.02467" iyz="0" izz="0.04411"/>
    </inertial>
    <visual>
      <origin rpy="0 0 1.570795" xyz="0 -0.09 0"/>
      <geometry>
        <mesh filename="package://msi_2k16_17_urdf/meshes/tyre.stl" scale="0.01 0.01 0.01"/>
      </geometry>
    </visual>
    <collision>
      <origin rpy="1.570795 0 0" xyz="0 0 0"/>
      <geometry>
        <cylinder length="0.18" radius="0.17"/>
      </geometry>
    </collision>
  </link>
  <gazebo reference="center_R_wheel_link">
    <mu1 value="1.0"/>
    <mu2 value="1.0"/>
    <kp value="10000000.0"/>
    <kd value="1.0"/>
    <fdir1 value="1 0 0"/>
    <material> Gazebo/FlatBlack</material>
  </gazebo>
  <joint name="center_R_wheel" type="continuous">
    <parent link="bogie_R"/>
    <child link="center_R_wheel_link"/>
    <origin rpy="0 0 0" xyz="0.2348 0.1146 -0.1932"/>
    <axis rpy="0 0 0" xyz="0 1 0"/>
  </joint>
  <transmission name="center_R_wheel_trans" type="SimpleTransmission">
    <type>transmission_interface/SimpleTransmission</type>
    <actuator name="center_R_wheel_motor">
      <mechanicalReduction>1</mechanicalReduction>
    </actuator>
    <joint name="center_R_wheel">
      <hardwareInterface>VelocityJointInterface</hardwareInterface>
    </joint>
  </transmission>
  <!-- Decorations MAcro -->
  <!-- <xacro:husky_decorate /> -->
  <!-- Differential Suspension -->
  <link name="differential">
    <visual>
      <geometry>
        <mesh filename="package://msi_2k16_17_urdf/meshes/differential.stl" scale="0.01 0.01 0.01"/>
      </geometry>
      <origin rpy="0 0 0" xyz="0 0 0"/>
      <material name="chassis"/>
    </visual>
    <inertial>
      <origin rpy="0 0 0" xyz="0 0 0"/>
      <mass value="1"/>
      <inertia ixx="1.0" ixy="0.0" ixz="0.0" iyy="1.0" iyz="0.0" izz="1.0"/>
    </inertial>
  </link>
  <!-- STATIC joints for differential -->
  <joint name="diff_to_chassis" type="fixed">
    <origin rpy="0 0 0" xyz="0.43 0 0"/>
    <parent link="base_link"/>
    <child link="differential"/>
  </joint>
  <!-- Join arm -->
  <!--<joint name="jaco_arm_base" type="fixed">
        <parent link="base_link" />
        <child link="base_link1" />
        <origin xyz=" -0.2 0 0" rpy="0 0 ${M_PI}" />
      </joint>-->
  <!--     <joint name="hokuyo_joint" type="fixed">
      <origin xyz="0 0 0" rpy="0 0 0" />
      <parent link="base_link" />
      <child link="base_laser_link" />
    </joint>
 -->
</robot>

